Workbook
Name Slicer_Category: #N/A

Sheet Cover
B2: Capstone project

Sheet Raw Data
A1: Date | B1: Region | C1: Product | D1: Category | E1: Units Sold | F1: Unit Price | G1: Sales Rep | H1: Customer
A2: 45821 | B2: South | C2: LAPTOP A15 | D2: computers | E2: 8 | F2: 2500000 | G2: Peter Obi | H2: bright solutions
A3: 45755 | B3: EAST | C3: tv 43q | D3: ELECTRONICS | E3: 6 | F3: 350000 | G3: Ifeanyi Okafor | H3: Musa Enterprises
A4: 45686 | B4: North | C4: PHONE X12 | D4: Mobile | E4: 14 | F4: 180000 | G4: fola balogun | H4: ZAINAB GLOBAL
A5: 17-MAY-2025 | B5: South | C5: MONITOR M2 4 | D5: PERIPHERALS | E5: 18 | F5: 65000 | G5: IFEANYI OKAFOR | H5: Jid eSuperstores
A6: 28-jan-2025 | B6: WEST | C6: Phone X12 | D6: Mobile | E6: 5 | F6: 180000 | G6: petero bi | H6: chkia mart
A7: 26-May-2025 | B7: east, | C7: Phone X12 | D7: mobile | E7: 19 | F7: 157427 | G7: IFEANYI OKAFOR | H7: Musa Enterprises
A8: 06-MAY-2025 | B8: WEST | C8: tv 43q | D8: Electronics | E8: 3 | F8: 350000 | G8: AISHA BELLO | H8: Chika Mart
A9: 10-Feb-2025 | B9: west | C9: monitor m24 | D9: peripherals | E9: 2 | F9: 65000 | G9: peter obi | H9: MUSA ENTERPIRSES
A10: 01-FEB-2025 | B10: East | C10: CAMERA C100 | D10: PHOTOGRAPHY | E10: 14 | F10: 175000 | G10: fola balogun | H10: BRIGTH SOLUTIONS
A11: 28-Jun-2025 | B11: West | C11: Tablet T8 | D11: mobile , | E11: 4 | F11: 150000 | G11: Peter Obi | H11: Alpha Retailers
A12: 18-Apr-2025 | B12: south | C12: TABLET T8 | D12: Mobile | E12: 20 | F12: 150000 | G12: fola balogun | H12: MUSA ENTERPRISES
A13: 25-Feb-2025 | B13: North | C13: Speake r S10 | D13: Audio | E13: 6 | F13: 85000 | G13: Aisha Bello | H13: Omega Wholesale
A14: 29-Apr-2025 | B14: WEST | C14: TABLET T8 | D14: Mobile | E14: 1 | F14: 150000 | G14: AISHA BELLO | H14: kelvin tech
A15: 02-Feb-2025 | B15: eats | C15: tv 43q | D15: ELECTRONICS | E15: 18 | F15: 35000 | G15: Chinedu Nwosu | H15: EMEKA TRADERS
A16: 15-Apr-2025 | B16: SOUTH | C16: Speaker S10 | D16: Audio . | E16: 2 | F16: 85000 | G16: ifeanyi okafor | H16: BRIGHT SOLUTIONS
... A86: 30-JAN-2025 | B86: east | C86: MONITOR M24 | D86: Perpiherals | E86: 18 | F86: 65000 | G86: CHINEDU NWOSU | H86: TOPE & SONS
A87: 31-Jan-2025 | B87: North | C87: laptop a15 | D87: Comupters | E87: 20 | F87: 250000 | G87: AISHA BELLO | H87: OMEGA WHOLESALE | I87: =LEFT(B87,1)
A88: 27-MAY-0225 | B88: East | C88: phone x12 | D88: Mobile | E88: 4 | F88: 180000 | G88: Aisha Bello | H88: Musa Enterprises
A89: 08-pAr-2025 | B89: South | C89: Tablet T8 | D89: mobile | E89: 5 | F89: 150000 | G89: Chinedu Nwosu | H89: Alpha Retailers
A90: 13-FEB-2025 | B90: West | C90: Laptop A15 | D90: COMPUTERS | E90: 11 | F90: 2500000 | G90: fola balogun | H90: Omega Wholesale
A91: 09-aMr-2025 | B91: East | C91: Laptop A15 | D91: Computers | E91: 20 | F91: 250000 | G91: IFEANYI O KAFOR | H91: femi tech ,
A92: 20-FEB-2052 | B92: west | C92: Speaker S10 | D92: AUDIO | E92: 7 | F92: 89233 | G92: fola balogun, | H92: FEMI TECH
A93: 19-Feb-2025 | B93: EAST , | C93: Laptop A15 | D93: COMPUTRES | E93: 5 | F93: 250000 | G93: Mary John | H93: TOEP & SONS
A94: 10-Apr-2025 | B94: East | C94: Camera C100, | D94: PHOTOGRAPHY | E94: 19 | F94: 175000 | G94: Mary John | H94: Kelvin Tech
A95: 21-May-2025 | B95: east | C95: TV 43Q | D95: Electronics | E95: 14 | F95: 350000 | G95: GRACE AMOS | H95: MUSA ENTERPRISES
A96: 26-jun-2025 | B96: east | C96: Camera C100 | D96: Photography | E96: 20 | F96: 175000 | G96: MARY JOHN . | H96: Bright Solutions
A97: 20-feb-2025 | B97: South | C97: SPEAKER S10 | D97: audio . | E97: 18 | F97: 85000 | G97: Peter Obi | H97: TOLA VENTURES
A98: 27-Ju-n2025 | B98: north | C98: camera c100 | D98: Photography | E98: 17 | F98: 175000 | G98: IFEANYI OKAFOR | H98: emeka traders
A99: 05-Feb-2025 | B99: South | C99: LAPTOP A15 | D99: COMPUTERS | E99: 20 | F99: 250000 | G99: Fola Balogun | H99: Musa Enterprises
... A101: 13-May-2025 | B101: WEST | C101: TABLET T8 | D101: Mobile | E101: 18 | F101: 150000 | G101: grace amos | H101: ALPHA RETAILERS

Sheet Solution
A1: Raw Date | B1: Day | C1: Month | D1: Year | E1: Date | F1: Region | G1: Product | H1: Category | I1: Units Sold | J1: Unit Price | K1: Total Sales | L1: Sales Rep | M1: Customer
A2: =UPPER(SUBSTITUTE(SUBSTITUTE(SUBSTITUTE(CLEAN('Raw Data'!A2),"-","")," ",""),".","")) -> 45821 | B2: =TEXT(SUBSTITUTE(SUBSTITUTE(SUBSTITUTE(Table1[[#This Row],[Raw Date]],"AMR","MAR"),"JNA","JAN"),"PAR","APR"),"D") -> 13 | C2: =TEXT(SUBSTITUTE(SUBSTITUTE(SUBSTITUTE(Table1[[#This Row],[Raw Date]],"AMR","MAR"),"JNA","JAN"),"PAR","APR"),"MMM") -> Jun | D2: =IF(YEAR(RIGHT(Table1[[#This Row],[Raw Date]],4))<>2025,2025,0) -> 2025 | E2: =_xlfn.CONCAT(B2&"-"&C2&"-"&D2) -> 13-Jun-2025 | F2: {=_xlfn.IFS(LEFT(SUBSTITUTE('Raw Data'!B2," ",""),1)="s", "South", LEFT(SUBSTITUTE('Raw Data'!B2," ",""),1)="n", "North",LEFT(SUBSTITUTE('Raw Data'!B2," ",""),1)="e","East",LEFT(SUBSTITUTE('Raw Data'!B2," ",""),1)="w","West")} -> South | G2: =PROPER(CLEAN(SUBSTITUTE(SUBSTITUTE(SUBSTITUTE('Raw Data'!C2," ",""),",",""),".",""))) -> Laptopa15 | H2: {=_xlfn.IFS(LEFT(SUBSTITUTE('Raw Data'!D2," ",""),2)="pe", "Peripherals",LEFT(SUBSTITUTE('Raw Data'!D2," ",""),2)="au", "Audio",LEFT(SUBSTITUTE('Raw Data'!D2," ",""),2)="co", "Computers", LEFT(SUBSTITUTE('Raw Data'!D2," ",""),1)="e", "Electronics",LEFT(SUBSTITUTE('Raw Data'!D2," ",""),2)="mo","Mobile",LEFT(SUBSTITUTE('Raw Data'!D2," ",""),2)="ph","Photography")} -> Computers | I2: ='Raw Data'!E2 -> 8 | J2: ='Raw Data'!F2 -> 2500000 | K2: =Table1[[#This Row],[Unit Price]]*Table1[[#This Row],[Units Sold]] -> 20000000 | L2: =UPPER(TRIM(CLEAN(SUBSTITUTE(SUBSTITUTE(SUBSTITUTE('Raw Data'!G2,",",""),".","")," ","")))) -> PETEROBI | M2: {=_xlfn.IFS(LEFT(SUBSTITUTE('Raw Data'!H2," ",""),1)="M", "Musa Enterprrises",LEFT(SUBSTITUTE('Raw Data'!H2," ",""),1)="o", "Omega Wholesale",LEFT(SUBSTITUTE('Raw Data'!H2," ",""),4)="Tola", "Tola Ventures", LEFT(SUBSTITUTE('Raw Data'!H2," ",""),1)="T", "Tope & Sons",LEFT(SUBSTITUTE('Raw Data'!H2," ",""),1)="z","Zainab Global",LEFT(SUBSTITUTE('Raw Data'!H2," ",""),2)="Ma","Maryam Ltd",LEFT(SUBSTITUTE('Raw Data'!H2," ",""),1)="j","Jide Superstores",LEFT(SUBSTITUTE('Raw Data'!H2," ",""),1)="f","Femi Tech",LEFT(SUBSTITUTE('Raw Data'!H2," ",""),1)="k","Kelvin Tech",LEFT(SUBSTITUTE('Raw Data'!H2," ",""),1)="A","Adewale Stores",LEFT(SUBSTITUTE('Raw Data'!H2," ",""),2)="Al","Alpha Retailers",LEFT(SUBSTITUTE('Raw Data'!H2," ",""),1)="b","Bright Solutions",LEFT(SUBSTITUTE('Raw Data'!H2," ",""),1)="c","Chika Mart",LEFT(SUBSTITUTE('Raw Data'!H2," ",""),1)="e","Emeka Traders")} -> Bright Solutions
A3: =UPPER(SUBSTITUTE(SUBSTITUTE(SUBSTITUTE(CLEAN('Raw Data'!A3),"-","")," ",""),".","")) -> 45755 | B3: =TEXT(SUBSTITUTE(SUBSTITUTE(SUBSTITUTE(Table1[[#This Row],[Raw Date]],"AMR","MAR"),"JNA","JAN"),"PAR","APR"),"D") -> 8 | C3: =TEXT(SUBSTITUTE(SUBSTITUTE(SUBSTITUTE(Table1[[#This Row],[Raw Date]],"AMR","MAR"),"JNA","JAN"),"PAR","APR"),"MMM") -> Apr | D3: =IF(YEAR(RIGHT(Table1[[#This Row],[Raw Date]],4))<>2025,2025,0) -> 2025 | E3: =_xlfn.CONCAT(B3&"-"&C3&"-"&D3) -> 8-Apr-2025 | F3: {=_xlfn.IFS(LEFT(SUBSTITUTE('Raw Data'!B3," ",""),1)="s", "South", LEFT(SUBSTITUTE('Raw Data'!B3," ",""),1)="n", "North",LEFT(SUBSTITUTE('Raw Data'!B3," ",""),1)="e","East",LEFT(SUBSTITUTE('Raw Data'!B3," ",""),1)="w","West")} -> East | G3: =PROPER(CLEAN(SUBSTITUTE(SUBSTITUTE(SUBSTITUTE('Raw Data'!C3," ",""),",",""),".",""))) -> Tv43Q | H3: {=_xlfn.IFS(LEFT(SUBSTITUTE('Raw Data'!D3," ",""),2)="pe", "Peripherals",LEFT(SUBSTITUTE('Raw Data'!D3," ",""),2)="au", "Audio",LEFT(SUBSTITUTE('Raw Data'!D3," ",""),2)="co", "Computers", LEFT(SUBSTITUTE('Raw Data'!D3," ",""),1)="e", "Electronics",LEFT(SUBSTITUTE('Raw Data'!D3," ",""),2)="mo","Mobile",LEFT(SUBSTITUTE('Raw Data'!D3," ",""),2)="ph","Photography")} -> Electronics | I3: ='Raw Data'!E3 -> 6 | J3: ='Raw Data'!F3 -> 350000 | K3: =Table1[[#This Row],[Unit Price]]*Table1[[#This Row],[Units Sold]] -> 2100000 | L3: =UPPER(TRIM(CLEAN(SUBSTITUTE(SUBSTITUTE(SUBSTITUTE('Raw Data'!G3,",",""),".","")," ","")))) -> IFEANYIOKAFOR | M3: {=_xlfn.IFS(LEFT(SUBSTITUTE('Raw Data'!H3," ",""),1)="M", "Musa Enterprrises",LEFT(SUBSTITUTE('Raw Data'!H3," ",""),1)="o", "Omega Wholesale",LEFT(SUBSTITUTE('Raw Data'!H3," ",""),4)="Tola", "Tola Ventures", LEFT(SUBSTITUTE('Raw Data'!H3," ",""),1)="T", "Tope & Sons",LEFT(SUBSTITUTE('Raw Data'!H3," ",""),1)="z","Zainab Global",LEFT(SUBSTITUTE('Raw Data'!H3," ",""),2)="Ma","Maryam Ltd",LEFT(SUBSTITUTE('Raw Data'!H3," ",""),1)="j","Jide Superstores",LEFT(SUBSTITUTE('Raw Data'!H3," ",""),1)="f","Femi Tech",LEFT(SUBSTITUTE('Raw Data'!H3," ",""),1)="k","Kelvin Tech",LEFT(SUBSTITUTE('Raw Data'!H3," ",""),1)="A","Adewale Stores",LEFT(SUBSTITUTE('Raw Data'!H3," ",""),2)="Al","Alpha Retailers",LEFT(SUBSTITUTE('Raw Data'!H3," ",""),1)="b","Bright Solutions",LEFT(SUBSTITUTE('Raw Data'!H3," ",""),1)="c","Chika Mart",LEFT(SUBSTITUTE('Raw Data'!H3," ",""),1)="e","Emeka Traders")} -> Musa Enterprrises
A4: =UPPER(SUBSTITUTE(SUBSTITUTE(SUBSTITUTE(CLEAN('Raw Data'!A4),"-","")," ",""),".","")) -> 45686 | B4: =TEXT(SUBSTITUTE(SUBSTITUTE(SUBSTITUTE(Table1[[#This Row],[Raw Date]],"AMR","MAR"),"JNA","JAN"),"PAR","APR"),"D") -> 29 | C4: =TEXT(SUBSTITUTE(SUBSTITUTE(SUBSTITUTE(Table1[[#This Row],[Raw Date]],"AMR","MAR"),"JNA","JAN"),"PAR","APR"),"MMM") -> Jan | D4: =IF(YEAR(RIGHT(Table1[[#This Row],[Raw Date]],4))<>2025,2025,0) -> 2025 | E4: =_xlfn.CONCAT(B4&"-"&C4&"-"&D4) -> 29-Jan-2025 | F4: {=_xlfn.IFS(LEFT(SUBSTITUTE('Raw Data'!B4," ",""),1)="s", "South", LEFT(SUBSTITUTE('Raw Data'!B4," ",""),1)="n", "North",LEFT(SUBSTITUTE('Raw Data'!B4," ",""),1)="e","East",LEFT(SUBSTITUTE('Raw Data'!B4," ",""),1)="w","West")} -> North | G4: =PROPER(CLEAN(SUBSTITUTE(SUBSTITUTE(SUBSTITUTE('Raw Data'!C4," ",""),",",""),".",""))) -> Phonex12 | H4: {=_xlfn.IFS(LEFT(SUBSTITUTE('Raw Data'!D4," ",""),2)="pe", "Peripherals",LEFT(SUBSTITUTE('Raw Data'!D4," ",""),2)="au", "Audio",LEFT(SUBSTITUTE('Raw Data'!D4," ",""),2)="co", "Computers", LEFT(SUBSTITUTE('Raw Data'!D4," ",""),1)="e", "Electronics",LEFT(SUBSTITUTE('Raw Data'!D4," ",""),2)="mo","Mobile",LEFT(SUBSTITUTE('Raw Data'!D4," ",""),2)="ph","Photography")} -> Mobile | I4: ='Raw Data'!E4 -> 14 | J4: ='Raw Data'!F4 -> 180000 | K4: =Table1[[#This Row],[Unit Price]]*Table1[[#This Row],[Units Sold]] -> 2520000 | L4: =UPPER(TRIM(CLEAN(SUBSTITUTE(SUBSTITUTE(SUBSTITUTE('Raw Data'!G4,",",""),".","")," ","")))) -> FOLABALOGUN | M4: {=_xlfn.IFS(LEFT(SUBSTITUTE('Raw Data'!H4," ",""),1)="M", "Musa Enterprrises",LEFT(SUBSTITUTE('Raw Data'!H4," ",""),1)="o", "Omega Wholesale",LEFT(SUBSTITUTE('Raw Data'!H4," ",""),4)="Tola", "Tola Ventures", LEFT(SUBSTITUTE('Raw Data'!H4," ",""),1)="T", "Tope & Sons",LEFT(SUBSTITUTE('Raw Data'!H4," ",""),1)="z","Zainab Global",LEFT(SUBSTITUTE('Raw Data'!H4," ",""),2)="Ma","Maryam Ltd",LEFT(SUBSTITUTE('Raw Data'!H4," ",""),1)="j","Jide Superstores",LEFT(SUBSTITUTE('Raw Data'!H4," ",""),1)="f","Femi Tech",LEFT(SUBSTITUTE('Raw Data'!H4," ",""),1)="k","Kelvin Tech",LEFT(SUBSTITUTE('Raw Data'!H4," ",""),1)="A","Adewale Stores",LEFT(SUBSTITUTE('Raw Data'!H4," ",""),2)="Al","Alpha Retailers",LEFT(SUBSTITUTE('Raw Data'!H4," ",""),1)="b","Bright Solutions",LEFT(SUBSTITUTE('Raw Data'!H4," ",""),1)="c","Chika Mart",LEFT(SUBSTITUTE('Raw Data'!H4," ",""),1)="e","Emeka Traders")} -> Zainab Global
A5: =UPPER(SUBSTITUTE(SUBSTITUTE(SUBSTITUTE(CLEAN('Raw Data'!A5),"-","")," ",""),".","")) -> 17MAY2025 | B5: =LEFT(Table1[[#This Row],[Raw Date]],2) -> 17 | C5: =SUBSTITUTE(SUBSTITUTE(SUBSTITUTE(MID(Table1[[#This Row],[Raw Date]],3,3),"AMR","MAR"),"JNA","JAN"),"PAR","APR") -> MAY | D5: =IF(YEAR(RIGHT(Table1[[#This Row],[Raw Date]],4))<>2025,2025,0) -> 2025 | E5: =_xlfn.CONCAT(B5&"-"&C5&"-"&D5) -> 17-MAY-2025 | F5: {=_xlfn.IFS(LEFT(SUBSTITUTE('Raw Data'!B5," ",""),1)="s", "South", LEFT(SUBSTITUTE('Raw Data'!B5," ",""),1)="n", "North",LEFT(SUBSTITUTE('Raw Data'!B5," ",""),1)="e","East",LEFT(SUBSTITUTE('Raw Data'!B5," ",""),1)="w","West")} -> South | G5: =PROPER(CLEAN(SUBSTITUTE(SUBSTITUTE(SUBSTITUTE('Raw Data'!C5," ",""),",",""),".",""))) -> Monitorm24 | H5: {=_xlfn.IFS(LEFT(SUBSTITUTE('Raw Data'!D5," ",""),2)="pe", "Peripherals",LEFT(SUBSTITUTE('Raw Data'!D5," ",""),2)="au", "Audio",LEFT(SUBSTITUTE('Raw Data'!D5," ",""),2)="co", "Computers", LEFT(SUBSTITUTE('Raw Data'!D5," ",""),1)="e", "Electronics",LEFT(SUBSTITUTE('Raw Data'!D5," ",""),2)="mo","Mobile",LEFT(SUBSTITUTE('Raw Data'!D5," ",""),2)="ph","Photography")} -> Peripherals | I5: ='Raw Data'!E5 -> 18 | J5: ='Raw Data'!F5 -> 65000 | K5: =Table1[[#This Row],[Unit Price]]*Table1[[#This Row],[Units Sold]] -> 1170000 | L5: =UPPER(TRIM(CLEAN(SUBSTITUTE(SUBSTITUTE(SUBSTITUTE('Raw Data'!G5,",",""),".","")," ","")))) -> IFEANYIOKAFOR | M5: {=_xlfn.IFS(LEFT(SUBSTITUTE('Raw Data'!H5," ",""),1)="M", "Musa Enterprrises",LEFT(SUBSTITUTE('Raw Data'!H5," ",""),1)="o", "Omega Wholesale",LEFT(SUBSTITUTE('Raw Data'!H5," ",""),4)="Tola", "Tola Ventures", LEFT(SUBSTITUTE('Raw Data'!H5," ",""),1)="T", "Tope & Sons",LEFT(SUBSTITUTE('Raw Data'!H5," ",""),1)="z","Zainab Global",LEFT(SUBSTITUTE('Raw Data'!H5," ",""),2)="Ma","Maryam Ltd",LEFT(SUBSTITUTE('Raw Data'!H5," ",""),1)="j","Jide Superstores",LEFT(SUBSTITUTE('Raw Data'!H5," ",""),1)="f","Femi Tech",LEFT(SUBSTITUTE('Raw Data'!H5," ",""),1)="k","Kelvin Tech",LEFT(SUBSTITUTE('Raw Data'!H5," ",""),1)="A","Adewale Stores",LEFT(SUBSTITUTE('Raw Data'!H5," ",""),2)="Al","Alpha Retailers",LEFT(SUBSTITUTE('Raw Data'!H5," ",""),1)="b","Bright Solutions",LEFT(SUBSTITUTE('Raw Data'!H5," ",""),1)="c","Chika Mart",LEFT(SUBSTITUTE('Raw Data'!H5," ",""),1)="e","Emeka Traders")} -> Jide Superstores
A6: =UPPER(SUBSTITUTE(SUBSTITUTE(SUBSTITUTE(CLEAN('Raw Data'!A6),"-","")," ",""),".","")) -> 28JAN2025 | B6: =LEFT(Table1[[#This Row],[Raw Date]],2) -> 28 | C6: =SUBSTITUTE(SUBSTITUTE(SUBSTITUTE(MID(Table1[[#This Row],[Raw Date]],3,3),"AMR","MAR"),"JNA","JAN"),"PAR","APR") -> JAN | D6: =IF(YEAR(RIGHT(Table1[[#This Row],[Raw Date]],4))<>2025,2025,0) -> 2025 | E6: =_xlfn.CONCAT(B6&"-"&C6&"-"&D6) -> 28-JAN-2025 | F6: {=_xlfn.IFS(LEFT(SUBSTITUTE('Raw Data'!B6," ",""),1)="s", "South", LEFT(SUBSTITUTE('Raw Data'!B6," ",""),1)="n", "North",LEFT(SUBSTITUTE('Raw Data'!B6," ",""),1)="e","East",LEFT(SUBSTITUTE('Raw Data'!B6," ",""),1)="w","West")} -> West | G6: =PROPER(CLEAN(SUBSTITUTE(SUBSTITUTE(SUBSTITUTE('Raw Data'!C6," ",""),",",""),".",""))) -> Phonex12 | H6: {=_xlfn.IFS(LEFT(SUBSTITUTE('Raw Data'!D6," ",""),2)="pe", "Peripherals",LEFT(SUBSTITUTE('Raw Data'!D6," ",""),2)="au", "Audio",LEFT(SUBSTITUTE('Raw Data'!D6," ",""),2)="co", "Computers", LEFT(SUBSTITUTE('Raw Data'!D6," ",""),1)="e", "Electronics",LEFT(SUBSTITUTE('Raw Data'!D6," ",""),2)="mo","Mobile",LEFT(SUBSTITUTE('Raw Data'!D6," ",""),2)="ph","Photography")} -> Mobile | I6: ='Raw Data'!E6 -> 5 | J6: ='Raw Data'!F6 -> 180000 | K6: =Table1[[#This Row],[Unit Price]]*Table1[[#This Row],[Units Sold]] -> 900000 | L6: =UPPER(TRIM(CLEAN(SUBSTITUTE(SUBSTITUTE(SUBSTITUTE('Raw Data'!G6,",",""),".","")," ","")))) -> PETEROBI | M6: {=_xlfn.IFS(LEFT(SUBSTITUTE('Raw Data'!H6," ",""),1)="M", "Musa Enterprrises",LEFT(SUBSTITUTE('Raw Data'!H6," ",""),1)="o", "Omega Wholesale",LEFT(SUBSTITUTE('Raw Data'!H6," ",""),4)="Tola", "Tola Ventures", LEFT(SUBSTITUTE('Raw Data'!H6," ",""),1)="T", "Tope & Sons",LEFT(SUBSTITUTE('Raw Data'!H6," ",""),1)="z","Zainab Global",LEFT(SUBSTITUTE('Raw Data'!H6," ",""),2)="Ma","Maryam Ltd",LEFT(SUBSTITUTE('Raw Data'!H6," ",""),1)="j","Jide Superstores",LEFT(SUBSTITUTE('Raw Data'!H6," ",""),1)="f","Femi Tech",LEFT(SUBSTITUTE('Raw Data'!H6," ",""),1)="k","Kelvin Tech",LEFT(SUBSTITUTE('Raw Data'!H6," ",""),1)="A","Adewale Stores",LEFT(SUBSTITUTE('Raw Data'!H6," ",""),2)="Al","Alpha Retailers",LEFT(SUBSTITUTE('Raw Data'!H6," ",""),1)="b","Bright Solutions",LEFT(SUBSTITUTE('Raw Data'!H6," ",""),1)="c","Chika Mart",LEFT(SUBSTITUTE('Raw Data'!H6," ",""),1)="e","Emeka Traders")} -> Chika Mart
A7: =UPPER(SUBSTITUTE(SUBSTITUTE(SUBSTITUTE(CLEAN('Raw Data'!A7),"-","")," ",""),".","")) -> 26MAY2025 | B7: =LEFT(Table1[[#This Row],[Raw Date]],2) -> 26 | C7: =SUBSTITUTE(SUBSTITUTE(SUBSTITUTE(MID(Table1[[#This Row],[Raw Date]],3,3),"AMR","MAR"),"JNA","JAN"),"PAR","APR") -> MAY | D7: =IF(YEAR(RIGHT(Table1[[#This Row],[Raw Date]],4))<>2025,2025,0) -> 2025 | E7: =_xlfn.CONCAT(B7&"-"&C7&"-"&D7) -> 26-MAY-2025 | F7: {=_xlfn.IFS(LEFT(SUBSTITUTE('Raw Data'!B7," ",""),1)="s", "South", LEFT(SUBSTITUTE('Raw Data'!B7," ",""),1)="n", "North",LEFT(SUBSTITUTE('Raw Data'!B7," ",""),1)="e","East",LEFT(SUBSTITUTE('Raw Data'!B7," ",""),1)="w","West")} -> East | G7: =PROPER(CLEAN(SUBSTITUTE(SUBSTITUTE(SUBSTITUTE('Raw Data'!C7," ",""),",",""),".",""))) -> Phonex12 | H7: {=_xlfn.IFS(LEFT(SUBSTITUTE('Raw Data'!D7," ",""),2)="pe", "Peripherals",LEFT(SUBSTITUTE('Raw Data'!D7," ",""),2)="au", "Audio",LEFT(SUBSTITUTE('Raw Data'!D7," ",""),2)="co", "Computers", LEFT(SUBSTITUTE('Raw Data'!D7," ",""),1)="e", "Electronics",LEFT(SUBSTITUTE('Raw Data'!D7," ",""),2)="mo","Mobile",LEFT(SUBSTITUTE('Raw Data'!D7," ",""),2)="ph","Photography")} -> Mobile | I7: ='Raw Data'!E7 -> 19 | J7: ='Raw Data'!F7 -> 157427 | K7: =Table1[[#This Row],[Unit Price]]*Table1[[#This Row],[Units Sold]] -> 2991113 | L7: =UPPER(TRIM(CLEAN(SUBSTITUTE(SUBSTITUTE(SUBSTITUTE('Raw Data'!G7,",",""),".","")," ","")))) -> IFEANYIOKAFOR | M7: {=_xlfn.IFS(LEFT(SUBSTITUTE('Raw Data'!H7," ",""),1)="M", "Musa Enterprrises",LEFT(SUBSTITUTE('Raw Data'!H7," ",""),1)="o", "Omega Wholesale",LEFT(SUBSTITUTE('Raw Data'!H7," ",""),4)="Tola", "Tola Ventures", LEFT(SUBSTITUTE('Raw Data'!H7," ",""),1)="T", "Tope & Sons",LEFT(SUBSTITUTE('Raw Data'!H7," ",""),1)="z","Zainab Global",LEFT(SUBSTITUTE('Raw Data'!H7," ",""),2)="Ma","Maryam Ltd",LEFT(SUBSTITUTE('Raw Data'!H7," ",""),1)="j","Jide Superstores",LEFT(SUBSTITUTE('Raw Data'!H7," ",""),1)="f","Femi Tech",LEFT(SUBSTITUTE('Raw Data'!H7," ",""),1)="k","Kelvin Tech",LEFT(SUBSTITUTE('Raw Data'!H7," ",""),1)="A","Adewale Stores",LEFT(SUBSTITUTE('Raw Data'!H7," ",""),2)="Al","Alpha Retailers",LEFT(SUBSTITUTE('Raw Data'!H7," ",""),1)="b","Bright Solutions",LEFT(SUBSTITUTE('Raw Data'!H7," ",""),1)="c","Chika Mart",LEFT(SUBSTITUTE('Raw Data'!H7," ",""),1)="e","Emeka Traders")} -> Musa Enterprrises
A8: =UPPER(SUBSTITUTE(SUBSTITUTE(SUBSTITUTE(CLEAN('Raw Data'!A8),"-","")," ",""),".","")) -> 06MAY2025 | B8: =LEFT(Table1[[#This Row],[Raw Date]],2) -> 06 | C8: =SUBSTITUTE(SUBSTITUTE(SUBSTITUTE(MID(Table1[[#This Row],[Raw Date]],3,3),"AMR","MAR"),"JNA","JAN"),"PAR","APR") -> MAY | D8: =IF(YEAR(RIGHT(Table1[[#This Row],[Raw Date]],4))<>2025,2025,0) -> 2025 | E8: =_xlfn.CONCAT(B8&"-"&C8&"-"&D8) -> 06-MAY-2025 | F8: {=_xlfn.IFS(LEFT(SUBSTITUTE('Raw Data'!B8," ",""),1)="s", "South", LEFT(SUBSTITUTE('Raw Data'!B8," ",""),1)="n", "North",LEFT(SUBSTITUTE('Raw Data'!B8," ",""),1)="e","East",LEFT(SUBSTITUTE('Raw Data'!B8," ",""),1)="w","West")} -> West | G8: =PROPER(CLEAN(SUBSTITUTE(SUBSTITUTE(SUBSTITUTE('Raw Data'!C8," ",""),",",""),".",""))) -> Tv43Q | H8: {=_xlfn.IFS(LEFT(SUBSTITUTE('Raw Data'!D8," ",""),2)="pe", "Peripherals",LEFT(SUBSTITUTE('Raw Data'!D8," ",""),2)="au", "Audio",LEFT(SUBSTITUTE('Raw Data'!D8," ",""),2)="co", "Computers", LEFT(SUBSTITUTE('Raw Data'!D8," ",""),1)="e", "Electronics",LEFT(SUBSTITUTE('Raw Data'!D8," ",""),2)="mo","Mobile",LEFT(SUBSTITUTE('Raw Data'!D8," ",""),2)="ph","Photography")} -> Electronics | I8: ='Raw Data'!E8 -> 3 | J8: ='Raw Data'!F8 -> 350000 | K8: =Table1[[#This Row],[Unit Price]]*Table1[[#This Row],[Units Sold]] -> 1050000 | L8: =UPPER(TRIM(CLEAN(SUBSTITUTE(SUBSTITUTE(SUBSTITUTE('Raw Data'!G8,",",""),".","")," ","")))) -> AISHABELLO | M8: {=_xlfn.IFS(LEFT(SUBSTITUTE('Raw Data'!H8," ",""),1)="M", "Musa Enterprrises",LEFT(SUBSTITUTE('Raw Data'!H8," ",""),1)="o", "Omega Wholesale",LEFT(SUBSTITUTE('Raw Data'!H8," ",""),4)="Tola", "Tola Ventures", LEFT(SUBSTITUTE('Raw Data'!H8," ",""),1)="T", "Tope & Sons",LEFT(SUBSTITUTE('Raw Data'!H8," ",""),1)="z","Zainab Global",LEFT(SUBSTITUTE('Raw Data'!H8," ",""),2)="Ma","Maryam Ltd",LEFT(SUBSTITUTE('Raw Data'!H8," ",""),1)="j","Jide Superstores",LEFT(SUBSTITUTE('Raw Data'!H8," ",""),1)="f","Femi Tech",LEFT(SUBSTITUTE('Raw Data'!H8," ",""),1)="k","Kelvin Tech",LEFT(SUBSTITUTE('Raw Data'!H8," ",""),1)="A","Adewale Stores",LEFT(SUBSTITUTE('Raw Data'!H8," ",""),2)="Al","Alpha Retailers",LEFT(SUBSTITUTE('Raw Data'!H8," ",""),1)="b","Bright Solutions",LEFT(SUBSTITUTE('Raw Data'!H8," ",""),1)="c","Chika Mart",LEFT(SUBSTITUTE('Raw Data'!H8," ",""),1)="e","Emeka Traders")} -> Chika Mart
A9: =UPPER(SUBSTITUTE(SUBSTITUTE(SUBSTITUTE(CLEAN('Raw Data'!A9),"-","")," ",""),".","")) -> 10FEB2025 | B9: =LEFT(Table1[[#This Row],[Raw Date]],2) -> 10 | C9: =SUBSTITUTE(SUBSTITUTE(SUBSTITUTE(MID(Table1[[#This Row],[Raw Date]],3,3),"AMR","MAR"),"JNA","JAN"),"PAR","APR") -> FEB | D9: =IF(YEAR(RIGHT(Table1[[#This Row],[Raw Date]],4))<>2025,2025,0) -> 2025 | E9: =_xlfn.CONCAT(B9&"-"&C9&"-"&D9) -> 10-FEB-2025 | F9: {=_xlfn.IFS(LEFT(SUBSTITUTE('Raw Data'!B9," ",""),1)="s", "South", LEFT(SUBSTITUTE('Raw Data'!B9," ",""),1)="n", "North",LEFT(SUBSTITUTE('Raw Data'!B9," ",""),1)="e","East",LEFT(SUBSTITUTE('Raw Data'!B9," ",""),1)="w","West")} -> West | G9: =PROPER(CLEAN(SUBSTITUTE(SUBSTITUTE(SUBSTITUTE('Raw Data'!C9," ",""),",",""),".",""))) -> Monitorm24 | H9: {=_xlfn.IFS(LEFT(SUBSTITUTE('Raw Data'!D9," ",""),2)="pe", "Peripherals",LEFT(SUBSTITUTE('Raw Data'!D9," ",""),2)="au", "Audio",LEFT(SUBSTITUTE('Raw Data'!D9," ",""),2)="co", "Computers", LEFT(SUBSTITUTE('Raw Data'!D9," ",""),1)="e", "Electronics",LEFT(SUBSTITUTE('Raw Data'!D9," ",""),2)="mo","Mobile",LEFT(SUBSTITUTE('Raw Data'!D9," ",""),2)="ph","Photography")} -> Peripherals | I9: ='Raw Data'!E9 -> 2 | J9: ='Raw Data'!F9 -> 65000 | K9: =Table1[[#This Row],[Unit Price]]*Table1[[#This Row],[Units Sold]] -> 130000 | L9: =UPPER(TRIM(CLEAN(SUBSTITUTE(SUBSTITUTE(SUBSTITUTE('Raw Data'!G9,",",""),".","")," ","")))) -> PETEROBI | M9: {=_xlfn.IFS(LEFT(SUBSTITUTE('Raw Data'!H9," ",""),1)="M", "Musa Enterprrises",LEFT(SUBSTITUTE('Raw Data'!H9," ",""),1)="o", "Omega Wholesale",LEFT(SUBSTITUTE('Raw Data'!H9," ",""),4)="Tola", "Tola Ventures", LEFT(SUBSTITUTE('Raw Data'!H9," ",""),1)="T", "Tope & Sons",LEFT(SUBSTITUTE('Raw Data'!H9," ",""),1)="z","Zainab Global",LEFT(SUBSTITUTE('Raw Data'!H9," ",""),2)="Ma","Maryam Ltd",LEFT(SUBSTITUTE('Raw Data'!H9," ",""),1)="j","Jide Superstores",LEFT(SUBSTITUTE('Raw Data'!H9," ",""),1)="f","Femi Tech",LEFT(SUBSTITUTE('Raw Data'!H9," ",""),1)="k","Kelvin Tech",LEFT(SUBSTITUTE('Raw Data'!H9," ",""),1)="A","Adewale Stores",LEFT(SUBSTITUTE('Raw Data'!H9," ",""),2)="Al","Alpha Retailers",LEFT(SUBSTITUTE('Raw Data'!H9," ",""),1)="b","Bright Solutions",LEFT(SUBSTITUTE('Raw Data'!H9," ",""),1)="c","Chika Mart",LEFT(SUBSTITUTE('Raw Data'!H9," ",""),1)="e","Emeka Traders")} -> Musa Enterprrises
A10: =UPPER(SUBSTITUTE(SUBSTITUTE(SUBSTITUTE(CLEAN('Raw Data'!A10),"-","")," ",""),".","")) -> 01FEB2025 | B10: =LEFT(Table1[[#This Row],[Raw Date]],2) -> 01 | C10: =SUBSTITUTE(SUBSTITUTE(SUBSTITUTE(MID(Table1[[#This Row],[Raw Date]],3,3),"AMR","MAR"),"JNA","JAN"),"PAR","APR") -> FEB | D10: =IF(YEAR(RIGHT(Table1[[#This Row],[Raw Date]],4))<>2025,2025,0) -> 2025 | E10: =_xlfn.CONCAT(B10&"-"&C10&"-"&D10) -> 01-FEB-2025 | F10: {=_xlfn.IFS(LEFT(SUBSTITUTE('Raw Data'!B10," ",""),1)="s", "South", LEFT(SUBSTITUTE('Raw Data'!B10," ",""),1)="n", "North",LEFT(SUBSTITUTE('Raw Data'!B10," ",""),1)="e","East",LEFT(SUBSTITUTE('Raw Data'!B10," ",""),1)="w","West")} -> East | G10: =PROPER(CLEAN(SUBSTITUTE(SUBSTITUTE(SUBSTITUTE('Raw Data'!C10," ",""),",",""),".",""))) -> Camerac100 | H10: {=_xlfn.IFS(LEFT(SUBSTITUTE('Raw Data'!D10," ",""),2)="pe", "Peripherals",LEFT(SUBSTITUTE('Raw Data'!D10," ",""),2)="au", "Audio",LEFT(SUBSTITUTE('Raw Data'!D10," ",""),2)="co", "Computers", LEFT(SUBSTITUTE('Raw Data'!D10," ",""),1)="e", "Electronics",LEFT(SUBSTITUTE('Raw Data'!D10," ",""),2)="mo","Mobile",LEFT(SUBSTITUTE('Raw Data'!D10," ",""),2)="ph","Photography")} -> Photography | I10: ='Raw Data'!E10 -> 14 | J10: ='Raw Data'!F10 -> 175000 | K10: =Table1[[#This Row],[Unit Price]]*Table1[[#This Row],[Units Sold]] -> 2450000 | L10: =UPPER(TRIM(CLEAN(SUBSTITUTE(SUBSTITUTE(SUBSTITUTE('Raw Data'!G10,",",""),".","")," ","")))) -> FOLABALOGUN | M10: {=_xlfn.IFS(LEFT(SUBSTITUTE('Raw Data'!H10," ",""),1)="M", "Musa Enterprrises",LEFT(SUBSTITUTE('Raw Data'!H10," ",""),1)="o", "Omega Wholesale",LEFT(SUBSTITUTE('Raw Data'!H10," ",""),4)="Tola", "Tola Ventures", LEFT(SUBSTITUTE('Raw Data'!H10," ",""),1)="T", "Tope & Sons",LEFT(SUBSTITUTE('Raw Data'!H10," ",""),1)="z","Zainab Global",LEFT(SUBSTITUTE('Raw Data'!H10," ",""),2)="Ma","Maryam Ltd",LEFT(SUBSTITUTE('Raw Data'!H10," ",""),1)="j","Jide Superstores",LEFT(SUBSTITUTE('Raw Data'!H10," ",""),1)="f","Femi Tech",LEFT(SUBSTITUTE('Raw Data'!H10," ",""),1)="k","Kelvin Tech",LEFT(SUBSTITUTE('Raw Data'!H10," ",""),1)="A","Adewale Stores",LEFT(SUBSTITUTE('Raw Data'!H10," ",""),2)="Al","Alpha Retailers",LEFT(SUBSTITUTE('Raw Data'!H10," ",""),1)="b","Bright Solutions",LEFT(SUBSTITUTE('Raw Data'!H10," ",""),1)="c","Chika Mart",LEFT(SUBSTITUTE('Raw Data'!H10," ",""),1)="e","Emeka Traders")} -> Bright Solutions
A11: =UPPER(SUBSTITUTE(SUBSTITUTE(SUBSTITUTE(CLEAN('Raw Data'!A11),"-","")," ",""),".","")) -> 28JUN2025 | B11: =LEFT(Table1[[#This Row],[Raw Date]],2) -> 28 | C11: =SUBSTITUTE(SUBSTITUTE(SUBSTITUTE(MID(Table1[[#This Row],[Raw Date]],3,3),"AMR","MAR"),"JNA","JAN"),"PAR","APR") -> JUN | D11: =IF(YEAR(RIGHT(Table1[[#This Row],[Raw Date]],4))<>2025,2025,0) -> 2025 | E11: =_xlfn.CONCAT(B11&"-"&C11&"-"&D11) -> 28-JUN-2025 | F11: {=_xlfn.IFS(LEFT(SUBSTITUTE('Raw Data'!B11," ",""),1)="s", "South", LEFT(SUBSTITUTE('Raw Data'!B11," ",""),1)="n", "North",LEFT(SUBSTITUTE('Raw Data'!B11," ",""),1)="e","East",LEFT(SUBSTITUTE('Raw Data'!B11," ",""),1)="w","West")} -> West | G11: =PROPER(CLEAN(SUBSTITUTE(SUBSTITUTE(SUBSTITUTE('Raw Data'!C11," ",""),",",""),".",""))) -> Tablett8 | H11: {=_xlfn.IFS(LEFT(SUBSTITUTE('Raw Data'!D11," ",""),2)="pe", "Peripherals",LEFT(SUBSTITUTE('Raw Data'!D11," ",""),2)="au", "Audio",LEFT(SUBSTITUTE('Raw Data'!D11," ",""),2)="co", "Computers", LEFT(SUBSTITUTE('Raw Data'!D11," ",""),1)="e", "Electronics",LEFT(SUBSTITUTE('Raw Data'!D11," ",""),2)="mo","Mobile",LEFT(SUBSTITUTE('Raw Data'!D11," ",""),2)="ph","Photography")} -> Mobile | I11: ='Raw Data'!E11 -> 4 | J11: ='Raw Data'!F11 -> 150000 | K11: =Table1[[#This Row],[Unit Price]]*Table1[[#This Row],[Units Sold]] -> 600000 | L11: =UPPER(TRIM(CLEAN(SUBSTITUTE(SUBSTITUTE(SUBSTITUTE('Raw Data'!G11,",",""),".","")," ","")))) -> PETEROBI | M11: {=_xlfn.IFS(LEFT(SUBSTITUTE('Raw Data'!H11," ",""),1)="M", "Musa Enterprrises",LEFT(SUBSTITUTE('Raw Data'!H11," ",""),1)="o", "Omega Wholesale",LEFT(SUBSTITUTE('Raw Data'!H11," ",""),4)="Tola", "Tola Ventures", LEFT(SUBSTITUTE('Raw Data'!H11," ",""),1)="T", "Tope & Sons",LEFT(SUBSTITUTE('Raw Data'!H11," ",""),1)="z","Zainab Global",LEFT(SUBSTITUTE('Raw Data'!H11," ",""),2)="Ma","Maryam Ltd",LEFT(SUBSTITUTE('Raw Data'!H11," ",""),1)="j","Jide Superstores",LEFT(SUBSTITUTE('Raw Data'!H11," ",""),1)="f","Femi Tech",LEFT(SUBSTITUTE('Raw Data'!H11," ",""),1)="k","Kelvin Tech",LEFT(SUBSTITUTE('Raw Data'!H11," ",""),1)="A","Adewale Stores",LEFT(SUBSTITUTE('Raw Data'!H11," ",""),2)="Al","Alpha Retailers",LEFT(SUBSTITUTE('Raw Data'!H11," ",""),1)="b","Bright Solutions",LEFT(SUBSTITUTE('Raw Data'!H11," ",""),1)="c","Chika Mart",LEFT(SUBSTITUTE('Raw Data'!H11," ",""),1)="e","Emeka Traders")} -> Adewale Stores
A12: =UPPER(SUBSTITUTE(SUBSTITUTE(SUBSTITUTE(CLEAN('Raw Data'!A12),"-","")," ",""),".","")) -> 18APR2025 | B12: =LEFT(Table1[[#This Row],[Raw Date]],2) -> 18 | C12: =SUBSTITUTE(SUBSTITUTE(SUBSTITUTE(MID(Table1[[#This Row],[Raw Date]],3,3),"AMR","MAR"),"JNA","JAN"),"PAR","APR") -> APR | D12: =IF(YEAR(RIGHT(Table1[[#This Row],[Raw Date]],4))<>2025,2025,0) -> 2025 | E12: =_xlfn.CONCAT(B12&"-"&C12&"-"&D12) -> 18-APR-2025 | F12: {=_xlfn.IFS(LEFT(SUBSTITUTE('Raw Data'!B12," ",""),1)="s", "South", LEFT(SUBSTITUTE('Raw Data'!B12," ",""),1)="n", "North",LEFT(SUBSTITUTE('Raw Data'!B12," ",""),1)="e","East",LEFT(SUBSTITUTE('Raw Data'!B12," ",""),1)="w","West")} -> South | G12: =PROPER(CLEAN(SUBSTITUTE(SUBSTITUTE(SUBSTITUTE('Raw Data'!C12," ",""),",",""),".",""))) -> Tablett8 | H12: {=_xlfn.IFS(LEFT(SUBSTITUTE('Raw Data'!D12," ",""),2)="pe", "Peripherals",LEFT(SUBSTITUTE('Raw Data'!D12," ",""),2)="au", "Audio",LEFT(SUBSTITUTE('Raw Data'!D12," ",""),2)="co", "Computers", LEFT(SUBSTITUTE('Raw Data'!D12," ",""),1)="e", "Electronics",LEFT(SUBSTITUTE('Raw Data'!D12," ",""),2)="mo","Mobile",LEFT(SUBSTITUTE('Raw Data'!D12," ",""),2)="ph","Photography")} -> Mobile | I12: ='Raw Data'!E12 -> 20 | J12: ='Raw Data'!F12 -> 150000 | K12: =Table1[[#This Row],[Unit Price]]*Table1[[#This Row],[Units Sold]] -> 3000000 | L12: =UPPER(TRIM(CLEAN(SUBSTITUTE(SUBSTITUTE(SUBSTITUTE('Raw Data'!G12,",",""),".","")," ","")))) -> FOLABALOGUN | M12: {=_xlfn.IFS(LEFT(SUBSTITUTE('Raw Data'!H12," ",""),1)="M", "Musa Enterprrises",LEFT(SUBSTITUTE('Raw Data'!H12," ",""),1)="o", "Omega Wholesale",LEFT(SUBSTITUTE('Raw Data'!H12," ",""),4)="Tola", "Tola Ventures", LEFT(SUBSTITUTE('Raw Data'!H12," ",""),1)="T", "Tope & Sons",LEFT(SUBSTITUTE('Raw Data'!H12," ",""),1)="z","Zainab Global",LEFT(SUBSTITUTE('Raw Data'!H12," ",""),2)="Ma","Maryam Ltd",LEFT(SUBSTITUTE('Raw Data'!H12," ",""),1)="j","Jide Superstores",LEFT(SUBSTITUTE('Raw Data'!H12," ",""),1)="f","Femi Tech",LEFT(SUBSTITUTE('Raw Data'!H12," ",""),1)="k","Kelvin Tech",LEFT(SUBSTITUTE('Raw Data'!H12," ",""),1)="A","Adewale Stores",LEFT(SUBSTITUTE('Raw Data'!H12," ",""),2)="Al","Alpha Retailers",LEFT(SUBSTITUTE('Raw Data'!H12," ",""),1)="b","Bright Solutions",LEFT(SUBSTITUTE('Raw Data'!H12," ",""),1)="c","Chika Mart",LEFT(SUBSTITUTE('Raw Data'!H12," ",""),1)="e","Emeka Traders")} -> Musa Enterprrises
A13: =UPPER(SUBSTITUTE(SUBSTITUTE(SUBSTITUTE(CLEAN('Raw Data'!A13),"-","")," ",""),".","")) -> 25FEB2025 | B13: =LEFT(Table1[[#This Row],[Raw Date]],2) -> 25 | C13: =SUBSTITUTE(SUBSTITUTE(SUBSTITUTE(MID(Table1[[#This Row],[Raw Date]],3,3),"AMR","MAR"),"JNA","JAN"),"PAR","APR") -> FEB | D13: =IF(YEAR(RIGHT(Table1[[#This Row],[Raw Date]],4))<>2025,2025,0) -> 2025 | E13: =_xlfn.CONCAT(B13&"-"&C13&"-"&D13) -> 25-FEB-2025 | F13: {=_xlfn.IFS(LEFT(SUBSTITUTE('Raw Data'!B13," ",""),1)="s", "South", LEFT(SUBSTITUTE('Raw Data'!B13," ",""),1)="n", "North",LEFT(SUBSTITUTE('Raw Data'!B13," ",""),1)="e","East",LEFT(SUBSTITUTE('Raw Data'!B13," ",""),1)="w","West")} -> North | G13: =PROPER(CLEAN(SUBSTITUTE(SUBSTITUTE(SUBSTITUTE('Raw Data'!C13," ",""),",",""),".",""))) -> Speakers10 | H13: {=_xlfn.IFS(LEFT(SUBSTITUTE('Raw Data'!D13," ",""),2)="pe", "Peripherals",LEFT(SUBSTITUTE('Raw Data'!D13," ",""),2)="au", "Audio",LEFT(SUBSTITUTE('Raw Data'!D13," ",""),2)="co", "Computers", LEFT(SUBSTITUTE('Raw Data'!D13," ",""),1)="e", "Electronics",LEFT(SUBSTITUTE('Raw Data'!D13," ",""),2)="mo","Mobile",LEFT(SUBSTITUTE('Raw Data'!D13," ",""),2)="ph","Photography")} -> Audio | I13: ='Raw Data'!E13 -> 6 | J13: ='Raw Data'!F13 -> 85000 | K13: =Table1[[#This Row],[Unit Price]]*Table1[[#This Row],[Units Sold]] -> 510000 | L13: =UPPER(TRIM(CLEAN(SUBSTITUTE(SUBSTITUTE(SUBSTITUTE('Raw Data'!G13,",",""),".","")," ","")))) -> AISHABELLO | M13: {=_xlfn.IFS(LEFT(SUBSTITUTE('Raw Data'!H13," ",""),1)="M", "Musa Enterprrises",LEFT(SUBSTITUTE('Raw Data'!H13," ",""),1)="o", "Omega Wholesale",LEFT(SUBSTITUTE('Raw Data'!H13," ",""),4)="Tola", "Tola Ventures", LEFT(SUBSTITUTE('Raw Data'!H13," ",""),1)="T", "Tope & Sons",LEFT(SUBSTITUTE('Raw Data'!H13," ",""),1)="z","Zainab Global",LEFT(SUBSTITUTE('Raw Data'!H13," ",""),2)="Ma","Maryam Ltd",LEFT(SUBSTITUTE('Raw Data'!H13," ",""),1)="j","Jide Superstores",LEFT(SUBSTITUTE('Raw Data'!H13," ",""),1)="f","Femi Tech",LEFT(SUBSTITUTE('Raw Data'!H13," ",""),1)="k","Kelvin Tech",LEFT(SUBSTITUTE('Raw Data'!H13," ",""),1)="A","Adewale Stores",LEFT(SUBSTITUTE('Raw Data'!H13," ",""),2)="Al","Alpha Retailers",LEFT(SUBSTITUTE('Raw Data'!H13," ",""),1)="b","Bright Solutions",LEFT(SUBSTITUTE('Raw Data'!H13," ",""),1)="c","Chika Mart",LEFT(SUBSTITUTE('Raw Data'!H13," ",""),1)="e","Emeka Traders")} -> Omega Wholesale
A14: =UPPER(SUBSTITUTE(SUBSTITUTE(SUBSTITUTE(CLEAN('Raw Data'!A14),"-","")," ",""),".","")) -> 29APR2025 | B14: =LEFT(Table1[[#This Row],[Raw Date]],2) -> 29 | C14: =SUBSTITUTE(SUBSTITUTE(SUBSTITUTE(MID(Table1[[#This Row],[Raw Date]],3,3),"AMR","MAR"),"JNA","JAN"),"PAR","APR") -> APR | D14: =IF(YEAR(RIGHT(Table1[[#This Row],[Raw Date]],4))<>2025,2025,0) -> 2025 | E14: =_xlfn.CONCAT(B14&"-"&C14&"-"&D14) -> 29-APR-2025 | F14: {=_xlfn.IFS(LEFT(SUBSTITUTE('Raw Data'!B14," ",""),1)="s", "South", LEFT(SUBSTITUTE('Raw Data'!B14," ",""),1)="n", "North",LEFT(SUBSTITUTE('Raw Data'!B14," ",""),1)="e","East",LEFT(SUBSTITUTE('Raw Data'!B14," ",""),1)="w","West")} -> West | G14: =PROPER(CLEAN(SUBSTITUTE(SUBSTITUTE(SUBSTITUTE('Raw Data'!C14," ",""),",",""),".",""))) -> Tablett8 | H14: {=_xlfn.IFS(LEFT(SUBSTITUTE('Raw Data'!D14," ",""),2)="pe", "Peripherals",LEFT(SUBSTITUTE('Raw Data'!D14," ",""),2)="au", "Audio",LEFT(SUBSTITUTE('Raw Data'!D14," ",""),2)="co", "Computers", LEFT(SUBSTITUTE('Raw Data'!D14," ",""),1)="e", "Electronics",LEFT(SUBSTITUTE('Raw Data'!D14," ",""),2)="mo","Mobile",LEFT(SUBSTITUTE('Raw Data'!D14," ",""),2)="ph","Photography")} -> Mobile | I14: ='Raw Data'!E14 -> 1 | J14: ='Raw Data'!F14 -> 150000 | K14: =Table1[[#This Row],[Unit Price]]*Table1[[#This Row],[Units Sold]] -> 150000 | L14: =UPPER(TRIM(CLEAN(SUBSTITUTE(SUBSTITUTE(SUBSTITUTE('Raw Data'!G14,",",""),".","")," ","")))) -> AISHABELLO | M14: {=_xlfn.IFS(LEFT(SUBSTITUTE('Raw Data'!H14," ",""),1)="M", "Musa Enterprrises",LEFT(SUBSTITUTE('Raw Data'!H14," ",""),1)="o", "Omega Wholesale",LEFT(SUBSTITUTE('Raw Data'!H14," ",""),4)="Tola", "Tola Ventures", LEFT(SUBSTITUTE('Raw Data'!H14," ",""),1)="T", "Tope & Sons",LEFT(SUBSTITUTE('Raw Data'!H14," ",""),1)="z","Zainab Global",LEFT(SUBSTITUTE('Raw Data'!H14," ",""),2)="Ma","Maryam Ltd",LEFT(SUBSTITUTE('Raw Data'!H14," ",""),1)="j","Jide Superstores",LEFT(SUBSTITUTE('Raw Data'!H14," ",""),1)="f","Femi Tech",LEFT(SUBSTITUTE('Raw Data'!H14," ",""),1)="k","Kelvin Tech",LEFT(SUBSTITUTE('Raw Data'!H14," ",""),1)="A","Adewale Stores",LEFT(SUBSTITUTE('Raw Data'!H14," ",""),2)="Al","Alpha Retailers",LEFT(SUBSTITUTE('Raw Data'!H14," ",""),1)="b","Bright Solutions",LEFT(SUBSTITUTE('Raw Data'!H14," ",""),1)="c","Chika Mart",LEFT(SUBSTITUTE('Raw Data'!H14," ",""),1)="e","Emeka Traders")} -> Kelvin Tech
A15: =UPPER(SUBSTITUTE(SUBSTITUTE(SUBSTITUTE(CLEAN('Raw Data'!A15),"-","")," ",""),".","")) -> 02FEB2025 | B15: =LEFT(Table1[[#This Row],[Raw Date]],2) -> 02 | C15: =SUBSTITUTE(SUBSTITUTE(SUBSTITUTE(MID(Table1[[#This Row],[Raw Date]],3,3),"AMR","MAR"),"JNA","JAN"),"PAR","APR") -> FEB | D15: =IF(YEAR(RIGHT(Table1[[#This Row],[Raw Date]],4))<>2025,2025,0) -> 2025 | E15: =_xlfn.CONCAT(B15&"-"&C15&"-"&D15) -> 02-FEB-2025 | F15: {=_xlfn.IFS(LEFT(SUBSTITUTE('Raw Data'!B15," ",""),1)="s", "South", LEFT(SUBSTITUTE('Raw Data'!B15," ",""),1)="n", "North",LEFT(SUBSTITUTE('Raw Data'!B15," ",""),1)="e","East",LEFT(SUBSTITUTE('Raw Data'!B15," ",""),1)="w","West")} -> East | G15: =PROPER(CLEAN(SUBSTITUTE(SUBSTITUTE(SUBSTITUTE('Raw Data'!C15," ",""),",",""),".",""))) -> Tv43Q | H15: {=_xlfn.IFS(LEFT(SUBSTITUTE('Raw Data'!D15," ",""),2)="pe", "Peripherals",LEFT(SUBSTITUTE('Raw Data'!D15," ",""),2)="au", "Audio",LEFT(SUBSTITUTE('Raw Data'!D15," ",""),2)="co", "Computers", LEFT(SUBSTITUTE('Raw Data'!D15," ",""),1)="e", "Electronics",LEFT(SUBSTITUTE('Raw Data'!D15," ",""),2)="mo","Mobile",LEFT(SUBSTITUTE('Raw Data'!D15," ",""),2)="ph","Photography")} -> Electronics | I15: ='Raw Data'!E15 -> 18 | J15: ='Raw Data'!F15 -> 35000 | K15: =Table1[[#This Row],[Unit Price]]*Table1[[#This Row],[Units Sold]] -> 630000 | L15: =UPPER(TRIM(CLEAN(SUBSTITUTE(SUBSTITUTE(SUBSTITUTE('Raw Data'!G15,",",""),".","")," ","")))) -> CHINEDUNWOSU | M15: {=_xlfn.IFS(LEFT(SUBSTITUTE('Raw Data'!H15," ",""),1)="M", "Musa Enterprrises",LEFT(SUBSTITUTE('Raw Data'!H15," ",""),1)="o", "Omega Wholesale",LEFT(SUBSTITUTE('Raw Data'!H15," ",""),4)="Tola", "Tola Ventures", LEFT(SUBSTITUTE('Raw Data'!H15," ",""),1)="T", "Tope & Sons",LEFT(SUBSTITUTE('Raw Data'!H15," ",""),1)="z","Zainab Global",LEFT(SUBSTITUTE('Raw Data'!H15," ",""),2)="Ma","Maryam Ltd",LEFT(SUBSTITUTE('Raw Data'!H15," ",""),1)="j","Jide Superstores",LEFT(SUBSTITUTE('Raw Data'!H15," ",""),1)="f","Femi Tech",LEFT(SUBSTITUTE('Raw Data'!H15," ",""),1)="k","Kelvin Tech",LEFT(SUBSTITUTE('Raw Data'!H15," ",""),1)="A","Adewale Stores",LEFT(SUBSTITUTE('Raw Data'!H15," ",""),2)="Al","Alpha Retailers",LEFT(SUBSTITUTE('Raw Data'!H15," ",""),1)="b","Bright Solutions",LEFT(SUBSTITUTE('Raw Data'!H15," ",""),1)="c","Chika Mart",LEFT(SUBSTITUTE('Raw Data'!H15," ",""),1)="e","Emeka Traders")} -> Emeka Traders
A16: =UPPER(SUBSTITUTE(SUBSTITUTE(SUBSTITUTE(CLEAN('Raw Data'!A16),"-","")," ",""),".","")) -> 15APR2025 | B16: =LEFT(Table1[[#This Row],[Raw Date]],2) -> 15 | C16: =SUBSTITUTE(SUBSTITUTE(SUBSTITUTE(MID(Table1[[#This Row],[Raw Date]],3,3),"AMR","MAR"),"JNA","JAN"),"PAR","APR") -> APR | D16: =IF(YEAR(RIGHT(Table1[[#This Row],[Raw Date]],4))<>2025,2025,0) -> 2025 | E16: =_xlfn.CONCAT(B16&"-"&C16&"-"&D16) -> 15-APR-2025 | F16: {=_xlfn.IFS(LEFT(SUBSTITUTE('Raw Data'!B16," ",""),1)="s", "South", LEFT(SUBSTITUTE('Raw Data'!B16," ",""),1)="n", "North",LEFT(SUBSTITUTE('Raw Data'!B16," ",""),1)="e","East",LEFT(SUBSTITUTE('Raw Data'!B16," ",""),1)="w","West")} -> South | G16: =PROPER(CLEAN(SUBSTITUTE(SUBSTITUTE(SUBSTITUTE('Raw Data'!C16," ",""),",",""),".",""))) -> Speakers10 | H16: {=_xlfn.IFS(LEFT(SUBSTITUTE('Raw Data'!D16," ",""),2)="pe", "Peripherals",LEFT(SUBSTITUTE('Raw Data'!D16," ",""),2)="au", "Audio",LEFT(SUBSTITUTE('Raw Data'!D16," ",""),2)="co", "Computers", LEFT(SUBSTITUTE('Raw Data'!D16," ",""),1)="e", "Electronics",LEFT(SUBSTITUTE('Raw Data'!D16," ",""),2)="mo","Mobile",LEFT(SUBSTITUTE('Raw Data'!D16," ",""),2)="ph","Photography")} -> Audio | I16: ='Raw Data'!E16 -> 2 | J16: ='Raw Data'!F16 -> 85000 | K16: =Table1[[#This Row],[Unit Price]]*Table1[[#This Row],[Units Sold]] -> 170000 | L16: =UPPER(TRIM(CLEAN(SUBSTITUTE(SUBSTITUTE(SUBSTITUTE('Raw Data'!G16,",",""),".","")," ","")))) -> IFEANYIOKAFOR | M16: {=_xlfn.IFS(LEFT(SUBSTITUTE('Raw Data'!H16," ",""),1)="M", "Musa Enterprrises",LEFT(SUBSTITUTE('Raw Data'!H16," ",""),1)="o", "Omega Wholesale",LEFT(SUBSTITUTE('Raw Data'!H16," ",""),4)="Tola", "Tola Ventures", LEFT(SUBSTITUTE('Raw Data'!H16," ",""),1)="T", "Tope & Sons",LEFT(SUBSTITUTE('Raw Data'!H16," ",""),1)="z","Zainab Global",LEFT(SUBSTITUTE('Raw Data'!H16," ",""),2)="Ma","Maryam Ltd",LEFT(SUBSTITUTE('Raw Data'!H16," ",""),1)="j","Jide Superstores",LEFT(SUBSTITUTE('Raw Data'!H16," ",""),1)="f","Femi Tech",LEFT(SUBSTITUTE('Raw Data'!H16," ",""),1)="k","Kelvin Tech",LEFT(SUBSTITUTE('Raw Data'!H16," ",""),1)="A","Adewale Stores",LEFT(SUBSTITUTE('Raw Data'!H16," ",""),2)="Al","Alpha Retailers",LEFT(SUBSTITUTE('Raw Data'!H16," ",""),1)="b","Bright Solutions",LEFT(SUBSTITUTE('Raw Data'!H16," ",""),1)="c","Chika Mart",LEFT(SUBSTITUTE('Raw Data'!H16," ",""),1)="e","Emeka Traders")} -> Bright Solutions
... A101: =UPPER(SUBSTITUTE(SUBSTITUTE(SUBSTITUTE(CLEAN('Raw Data'!A101),"-","")," ",""),".","")) -> 13MAY2025 | B101: =LEFT(Table1[[#This Row],[Raw Date]],2) -> 13 | C101: =SUBSTITUTE(SUBSTITUTE(SUBSTITUTE(MID(Table1[[#This Row],[Raw Date]],3,3),"AMR","MAR"),"JNA","JAN"),"PAR","APR") -> MAY | D101: =IF(YEAR(RIGHT(Table1[[#This Row],[Raw Date]],4))<>2025,2025,0) -> 2025 | E101: =_xlfn.CONCAT(B101&"-"&C101&"-"&D101) -> 13-MAY-2025 | F101: {=_xlfn.IFS(LEFT(SUBSTITUTE('Raw Data'!B101," ",""),1)="s", "South", LEFT(SUBSTITUTE('Raw Data'!B101," ",""),1)="n", "North",LEFT(SUBSTITUTE('Raw Data'!B101," ",""),1)="e","East",LEFT(SUBSTITUTE('Raw Data'!B101," ",""),1)="w","West")} -> West | G101: =PROPER(CLEAN(SUBSTITUTE(SUBSTITUTE(SUBSTITUTE('Raw Data'!C101," ",""),",",""),".",""))) -> Tablett8 | H101: {=_xlfn.IFS(LEFT(SUBSTITUTE('Raw Data'!D101," ",""),2)="pe", "Peripherals",LEFT(SUBSTITUTE('Raw Data'!D101," ",""),2)="au", "Audio",LEFT(SUBSTITUTE('Raw Data'!D101," ",""),2)="co", "Computers", LEFT(SUBSTITUTE('Raw Data'!D101," ",""),1)="e", "Electronics",LEFT(SUBSTITUTE('Raw Data'!D101," ",""),2)="mo","Mobile",LEFT(SUBSTITUTE('Raw Data'!D101," ",""),2)="ph","Photography")} -> Mobile | I101: ='Raw Data'!E101 -> 18 | J101: ='Raw Data'!F101 -> 150000 | K101: =Table1[[#This Row],[Unit Price]]*Table1[[#This Row],[Units Sold]] -> 2700000 | L101: =UPPER(TRIM(CLEAN(SUBSTITUTE(SUBSTITUTE(SUBSTITUTE('Raw Data'!G101,",",""),".","")," ","")))) -> GRACEAMOS | M101: {=_xlfn.IFS(LEFT(SUBSTITUTE('Raw Data'!H101," ",""),1)="M", "Musa Enterprrises",LEFT(SUBSTITUTE('Raw Data'!H101," ",""),1)="o", "Omega Wholesale",LEFT(SUBSTITUTE('Raw Data'!H101," ",""),4)="Tola", "Tola Ventures", LEFT(SUBSTITUTE('Raw Data'!H101," ",""),1)="T", "Tope & Sons",LEFT(SUBSTITUTE('Raw Data'!H101," ",""),1)="z","Zainab Global",LEFT(SUBSTITUTE('Raw Data'!H101," ",""),2)="Ma","Maryam Ltd",LEFT(SUBSTITUTE('Raw Data'!H101," ",""),1)="j","Jide Superstores",LEFT(SUBSTITUTE('Raw Data'!H101," ",""),1)="f","Femi Tech",LEFT(SUBSTITUTE('Raw Data'!H101," ",""),1)="k","Kelvin Tech",LEFT(SUBSTITUTE('Raw Data'!H101," ",""),1)="A","Adewale Stores",LEFT(SUBSTITUTE('Raw Data'!H101," ",""),2)="Al","Alpha Retailers",LEFT(SUBSTITUTE('Raw Data'!H101," ",""),1)="b","Bright Solutions",LEFT(SUBSTITUTE('Raw Data'!H101," ",""),1)="c","Chika Mart",LEFT(SUBSTITUTE('Raw Data'!H101," ",""),1)="e","Emeka Traders")} -> Adewale Stores
I102: =SUBTOTAL(109,Table1[Units Sold]) -> 1141 | K102: =SUBTOTAL(109,Table1[Total Sales]) -> 302680445
K104: 293725814
K105: =Table1[[#Totals],[Total Sales]]-K104 -> 8954631

Sheet Pivot Table
A2: TOTAL SALES BY REGION | D2: BEST SELLING PRODUCT | G2: SALES PERFORMANCE BY SALES REP | J2: TOTAL SALES BY CATEGORY
A3: Row Labels | B3: Sum of Total Sales | D3: Row Labels | E3: Sum of Units Sold | G3: Row Labels | H3: Sum of Total Sales | J3: Row Labels | K3: Sum of Total Sales
A4: East | B4: 79518498 | D4: Tablett8 | E4: 226 | G4: PETEROBI | H4: 87790000 | J4: Audio | K4: 8954631
A5: North | B5: 39490000 | D5: Tv43Q | E5: 215 | G5: FOLABALOGUN | H5: 58707487 | J5: Computers | K5: 134375000
A6: South | B6: 68129460 | D6: Laptopa15 | E6: 191 | G6: GRACEAMOS | H6: 42610000 | J6: Electronics | K6: 63689500
A7: West | B7: 115542487 | D7: Monitorm24 | E7: 166 | G7: CHINEDUNWOSU | H7: 36226885 | J7: Mobile | K7: 48231113
A8: Grand Total | B8: 302680445 | D8: Camerac100 | E8: 134 | G8: IFEANYIOKAFOR | H8: 28986113 | J8: Peripherals | K8: 21880201
D9: Speakers10 | E9: 105 | G9: MARYJOHN | H9: 20919960 | J9: Photography | K9: 25550000
D10: Phonex12 | E10: 82 | G10: AISHABELLO | H10: 18690000 | J10: Grand Total | K10: 302680445
D11: Camerac010 | E11: 12 | G11: JOBAUSTIN | H11: 5250000
A12: SALES UNIT BY SALES REP | D12: Unknown | E12: 10 | G12: PRAISEODUNAYO | H12: 2850000
A13: Row Labels | B13: Sum of Units Sold | D13: Grand Total | E13: 1141 | G13: ABAJOEL | H13: 650000
A14: CHINEDUNWOSU | B14: 224 | G14: Grand Total | H14: 302680445
A15: FOLABALOGUN | B15: 195
A16: GRACEAMOS | B16: 177 | D16: REGION WITH THE HIGHEST SALES PRODUCT
A17: IFEANYIOKAFOR | B17: 151 | D17: Sum of Total Sales | E17: REGION
A18: AISHABELLO | B18: 124 | D18: Row Labels | E18: East | F18: North | G18: South | H18: West | I18: Grand Total
A19: PETEROBI | B19: 121 | D19: Camerac010 | E19: 2100000 | I19: 2100000
A20: MARYJOHN | B20: 105 | D20: Camerac100 | E20: 15925000 | F20: 5250000 | G20: 1750000 | H20: 525000 | I20: 23450000
A21: PRAISEODUNAYO | B21: 19 | D21: Laptopa15 | E21: 18000000 | F21: 8250000 | G21: 25875000 | H21: 82250000 | I21: 134375000
A22: JOBAUSTIN | B22: 15 | D22: Monitorm24 | E22: 13552385 | F22: 1105000 | G22: 3479960 | H22: 3092856 | I22: 21230201
A23: ABAJOEL | B23: 10 | D23: Phonex12 | E23: 6051113 | F23: 5940000 | G23: 1440000 | H23: 900000 | I23: 14331113
A24: Grand Total | B24: 1141 | D24: Speakers10 | E24: 3910000 | F24: 1445000 | G24: 2975000 | H24: 624631 | I24: 8954631
D25: Tablett8 | E25: 11700000 | F25: 4200000 | G25: 10500000 | H25: 7500000 | I25: 33900000
D26: Tv43Q | E26: 7630000 | F26: 13300000 | G26: 22109500 | H26: 20650000 | I26: 63689500
D27: Unknown | E27: 650000 | I27: 650000
D28: Grand Total | E28: 79518498 | F28: 39490000 | G28: 68129460 | H28: 115542487 | I28: 302680445
A31: PERCENTAGE SALES OF PRODUCT IN CATEGORY | E31: TOP 5 CUSTOMERS
A32: Row Labels | B32: % of Total | C32: Sum of Total Sales | E32: Row Labels | F32: Sum of Total Sales
A33: Computers | B33: 0.44395005 | C33: 134375000 | E33: Omega Wholesale | F33: 89559500
A34: Laptopa15 | B34: 0.44395005 | C34: 134375000 | E34: Musa Enterprrises | F34: 39626113
A35: Electronics | B35: 0.21041828 | C35: 63689500 | E35: Bright Solutions | F35: 31715000
A36: Tv43Q | B36: 0.21041828 | C36: 63689500 | E36: Femi Tech | F36: 31117487
A37: Mobile | B37: 0.15934664 | C37: 48231113 | E37: Jide Superstores | F37: 23270000
A38: Tablett8 | B38: 0.11199931 | C38: 33900000 | E38: Grand Total | F38: 215288100
A39: Phonex12 | B39: 0.047347337 | C39: 14331113
A40: Photography | B40: 0.084412457 | C40: 25550000
A41: Camerac100 | B41: 0.077474447 | C41: 23450000
A42: Camerac010 | B42: 0.0069380102 | C42: 2100000
A43: Peripherals | B43: 0.072288122 | C43: 21880201
...

Sheet DASHBOARD
